Workbook

Sheet Assessment
A1: AI Governance Maturity Assessment — Choice · Cost · Control
A2: Rate each statement 1–5: 1 Not in place · 2 Early / ad hoc · 3 Partially in place · 4 Mostly in place · 5 Fully in place
A4: # | B4: Statement | C4: Your Score (1–5)
A5: CHOICE
A6: 1 | B6: We have a central governance layer for our data AND AI assets (models, MCP servers, tools, agents, connections). | C6: 1
A7: 2 | B7: Access to foundation models / LLMs is centrally controlled, with role or group based access (not per-developer keys). | C7: 2
A8: 3 | B8: We have a single inventory of which models, MCP servers, agents, and tools are deployed, accessible, and discoverable. | C8: 3
A9: 4 | B9: We grant and revoke access to AI assets using the same roles/privileges we use for data. | C9: 4
A10: 5 | B10: Access decisions for AI assets are tied to user identity, not just service accounts. | C10: 5
A11: 6 | B11: Agents access external systems with the requesting user's own permissions (on-behalf-of), not shared or service principal accounts. | C11: 1
A12: 7 | B12: Model selection is governed by a defined approval process with an owner and we can ban a model provider or family org-wide in a single action (by provider, country of origin, or approval status). | C12: 2
A13: 8 | B13: Coding-agent model choice and tool access (approved model list, read-vs-write tool restrictions) are defined and enforced centrally. | C13: 3
A14: 9 | B14: Our AI assets (vendor- or self hosted) are routed through the governed control plane, not connected directly and unmanaged. | C14: 4
A15: 10 | B15: We have the option to use the latest proprietary and open weight frontier models from leading AI labs | C15: 4
A17: COST
A18: 11 | B18: We have unified visibility into our AI spend across models, providers, teams, and use cases. | C18: 1
A19: 12 | B19: We route each request to an appropriately-priced model and can quantify the savings versus always using the most expensive model. | C19: 2
A20: 13 | B20: We can attribute AI cost granularly by user, team, model, tool, use case, or tag. | C20: 3
A21: 14 | B21: We set and enforce AI budgets at the user, team, workspace, or account level and assign an appropriate owner. | C21: 4
A22: 15 | B22: We can link AI-completed tasks with AI spend to understand which models are most efficient for our work | C22: 5
A23: 16 | B23: We enforce rate limits (QPM / TPM) on model and MCP services to manage capacity and cost. | C23: 1
A24: 17 | B24: We have hard spend caps that automatically halt or throttle requests when a budget is exceeded — not just soft alerts. | C24: 1
A25: 18 | B25: We detect runaway or anomalous AI spend early (retry loops, weekend experiments, sudden 100x spikes). | C25: 1
A26: 19 | B26: Coding-agent spend is attributable by team, repo, or cost center — not a single vendor invoice line — and we know whether seat-based or token-based is the bigger driver. | C26: 1
A27: 20 | B27: AI spend spikes tie to an approved business case / owner (purchase-order or chargeback discipline). | C27: 1
A29: CONTROL
A30: 21 | B30: We apply content guardrails / service policies to AI requests AND responses, authored centrally as one layer across the models and services we register. | C30: 1
A31: 22 | B31: We detect and handle PII/PHI/PCI in AI requests and responses to meet compliance requirements, and we distinguish masking from blocking. | C31: 1
A32: 23 | B32: We have protections against prompt injection / jailbreak and policy violations, including for customer-facing AI. | C32: 1
A33: 24 | B33: Hallucination / groundedness requirements are addressed — responses can be flagged or blocked, or required to cite sources. | C33: 1
A34: 25 | B34: We have a defined policy-authoring process (who decides what counts as a violation, how policies are versioned) with per-use-case or per-agent policies, not one-size-fits-all. | C34: 1
A35: 26 | B35: We can allow, deny, or require approval (ALLOW / DENY / ASK) for specific AI actions based on user, agent, model, or content. | C35: 1
A36: 27 | B36: All AI requests, responses, and policy actions are logged for audit; we can demonstrate logs for regulatory obligations (GLBA, HIPAA, FedRAMP, GDPR), scan for leaked secrets, and enforce token rotation / OAuth / secret management. | C36: 2
A37: 28 | B37: We have end-to-end, developer-level tracing across model and MCP tool activity, attributable to named users and correlated with resource-level access events (who did what, via which agent, to which resource). | C37: 1
A38: 29 | B38: We have unified dashboards for AI usage, cost, and performance from one source of truth, and AI activity feeds our security information and event management system the way database or application activity does — including external and on-prem AI via a standard protocol (e.g., OpenTelemetry). | C38: 1
A39: 30 | B39: We use reliability features such as fallbacks, traffic splitting across model versions or families, and regional deployments with automatic failover; coding-agent activity is monitored centrally. | C39: 1

Sheet Results
A1: AI Governance Maturity — Results
A2: Scores pull automatically from the Assessment tab — enter your 1–5 scores there and this tab updates live. What to do by score: 1–2 → the “If scored 1–2” column · 3–4 → “If scored 3–4” · 5 → ✅ Validate in POC. A foundational item scored 1–2 is a ⛔ Blocking Prerequisite; other gaps are 🎯 Prove in Workshop or 🔍 Explore in Accelerator.
A4: Pillar | B4: Avg Score (1–5) | C4: Recommended actions
A5: Choice | B5: =IFERROR(AVERAGE(Assessment!C6:C15),"—") -> 2.9 | C5: ⛔ Blocking Prerequisites | D5: =SUMPRODUCT(--ISNUMBER(SEARCH("Blocking Prerequisite",$F$20:$F$49))) -> 5
A6: Cost | B6: =IFERROR(AVERAGE(Assessment!C18:C27),"—") -> 2 | C6: 🎯 Prove in Workshop | D6: =SUMPRODUCT(--ISNUMBER(SEARCH("Prove in Workshop",$F$20:$F$49))) -> 19
A7: Control | B7: =IFERROR(AVERAGE(Assessment!C30:C39),"—") -> 1.1 | C7: 🔍 Explore in Accelerator | D7: =SUMPRODUCT(--ISNUMBER(SEARCH("Explore in Accelerator",$F$20:$F$49))) -> 4
C8: ✅ Validate in POC | D8: =SUMPRODUCT(--ISNUMBER(SEARCH("Validate in POC",$F$20:$F$49))) -> 2
A9: Overall Score | B9: =IFERROR(AVERAGE(Assessment!C6:C15,Assessment!C18:C27,Assessment!C30:C39),"—") -> 2 | C9: 🚀 Top accelerator fit | D9: {=IFERROR(INDEX($C$12:$C$17,MATCH(MAX($D$12:$D$17),$D$12:$D$17,0)),"—")} -> Policies & Guardrails
A10: Maturity Level | B10: =IF(NOT(ISNUMBER($B$9)),"— (no scores yet)",IFS($B$9>=4.5,"L5 · Optimised",$B$9>=4,"L4 · Managed",$B$9>=3,"L3 · Established",$B$9>=2,"L2 · Developing",$B$9>=1,"L1 · Ad hoc / Ungoverned")) -> L2 · Developing
A11: Readiness (%) | B11: =IFERROR(TEXT($B$9/5*100,"0.0")&"%","—") -> 40.0% | C11: Accelerator | D11: Fit (avg gap — higher = better fit)
C12: MCP Servers | D12: =IFERROR(ROUND(SUMPRODUCT((($B$20:$B$49="choice_obo")+($B$20:$B$49="control_allow_deny_ask")+($B$20:$B$49="choice_single_inventory"))*N($J$20:$J$49))/SUMPRODUCT((($B$20:$B$49="choice_obo")+($B$20:$B$49="control_allow_deny_ask")+($B$20:$B$49="choice_single_inventory"))*($J$20:$J$49<>"")),2),"") -> 3.33
C13: Agents | D13: =IFERROR(ROUND(SUMPRODUCT((($B$20:$B$49="choice_single_inventory")+($B$20:$B$49="choice_uc_central")+($B$20:$B$49="control_tracing_correlation")+($B$20:$B$49="choice_cross_platform_inventory"))*N($J$20:$J$49))/SUMPRODUCT((($B$20:$B$49="choice_single_inventory")+($B$20:$B$49="choice_uc_central")+($B$20:$B$49="control_tracing_correlation")+($B$20:$B$49="choice_cross_platform_inventory"))*($J$20:$J$49<>"")),2),"") -> 3.33
C14: External Providers | D14: =IFERROR(ROUND(SUMPRODUCT((($B$20:$B$49="choice_external_routed")+($B$20:$B$49="choice_model_governance")+($B$20:$B$49="control_audit_secret"))*N($J$20:$J$49))/SUMPRODUCT((($B$20:$B$49="choice_external_routed")+($B$20:$B$49="choice_model_governance")+($B$20:$B$49="control_audit_secret"))*($J$20:$J$49<>"")),2),"") -> 2.33
C15: Coding Agents | D15: =IFERROR(ROUND(SUMPRODUCT((($B$20:$B$49="choice_coding_agents")+($B$20:$B$49="cost_coding_agents")+($B$20:$B$49="cost_rate_limits"))*N($J$20:$J$49))/SUMPRODUCT((($B$20:$B$49="choice_coding_agents")+($B$20:$B$49="cost_coding_agents")+($B$20:$B$49="cost_rate_limits"))*($J$20:$J$49<>"")),2),"") -> 3.33
C16: Policies & Guardrails | D16: =IFERROR(ROUND(SUMPRODUCT((($B$20:$B$49="control_guardrails")+($B$20:$B$49="control_pii")+($B$20:$B$49="control_prompt_injection")+($B$20:$B$49="control_groundedness"))*N($J$20:$J$49))/SUMPRODUCT((($B$20:$B$49="control_guardrails")+($B$20:$B$49="control_pii")+($B$20:$B$49="control_prompt_injection")+($B$20:$B$49="control_groundedness"))*($J$20:$J$49<>"")),2),"") -> 4
C17: Skills | D17: =IFERROR(ROUND(SUMPRODUCT((($B$20:$B$49="choice_coding_agents")+($B$20:$B$49="control_policy_authoring"))*N($J$20:$J$49))/SUMPRODUCT((($B$20:$B$49="choice_coding_agents")+($B$20:$B$49="control_policy_authoring"))*($J$20:$J$49<>"")),2),"") -> 3
A19: Pillar | B19: Maturity ID | C19: Statement | D19: Type | E19: Your score | F19: What to do | G19: If scored 1–2 | H19: If scored 3–4 | I19: If scored 5 | J19: Gap (5−score)
A20: Choice | B20: choice_uc_central | C20: =Assessment!B6 -> We have a central governance layer for our data AND AI assets (models, MCP servers, tools, agents, connections). | D20: foundational | E20: =Assessment!C6 -> 1 | F20: =IF(E20="","",IF(E20<=2,G20,IF(E20<=4,H20,I20))) -> ⛔ Blocking Prerequisite: Unity Catalog enabled with foundation models (+ a catalog & running warehouse) | G20: ⛔ Blocking Prerequisite: Unity Catalog enabled with foundation models (+ a catalog & running warehouse) | H20: 🎯 Prove in Workshop: choice_list_endpoints, choice_model_services, control_agent_service | I20: ✅ Validate in POC | J20: =IF(E20="","",5-E20) -> 4
A21: Choice | B21: choice_central_model_access | C21: =Assessment!B7 -> Access to foundation models / LLMs is centrally controlled, with role or group based access (not per-developer keys). | D21: foundational | E21: =Assessment!C7 -> 2 | F21: =IF(E21="","",IF(E21<=2,G21,IF(E21<=4,H21,I21))) -> ⛔ Blocking Prerequisite: Unity AI Gateway enabled on the account and workspace | G21: ⛔ Blocking Prerequisite: Unity AI Gateway enabled on the account and workspace | H21: 🎯 Prove in Workshop: choice_model_services, choice_default_access | I21: ✅ Validate in POC | J21: =IF(E21="","",5-E21) -> 3
A22: Choice | B22: choice_single_inventory | C22: =Assessment!B8 -> We have a single inventory of which models, MCP servers, agents, and tools are deployed, accessible, and discoverable. | D22: capability | E22: =Assessment!C8 -> 3 | F22: =IF(E22="","",IF(E22<=2,G22,IF(E22<=4,H22,I22))) -> 🎯 Prove in Workshop: choice_list_endpoints, control_agent_service | G22: 🎯 Prove in Workshop: choice_list_endpoints, control_agent_service | H22: 🎯 Prove in Workshop: choice_list_endpoints, control_agent_service | I22: ✅ Validate in POC | J22: =IF(E22="","",5-E22) -> 2
A23: Choice | B23: choice_same_privileges | C23: =Assessment!B9 -> We grant and revoke access to AI assets using the same roles/privileges we use for data. | D23: capability | E23: =Assessment!C9 -> 4 | F23: =IF(E23="","",IF(E23<=2,G23,IF(E23<=4,H23,I23))) -> 🎯 Prove in Workshop: choice_model_services, choice_default_access | G23: 🎯 Prove in Workshop: choice_model_services, choice_default_access | H23: 🎯 Prove in Workshop: choice_model_services, choice_default_access | I23: ✅ Validate in POC | J23: =IF(E23="","",5-E23) -> 1
A24: Choice | B24: choice_identity_aware | C24: =Assessment!B10 -> Access decisions for AI assets are tied to user identity, not just service accounts. | D24: capability | E24: =Assessment!C10 -> 5 | F24: =IF(E24="","",IF(E24<=2,G24,IF(E24<=4,H24,I24))) -> ✅ Validate in POC | G24: 🎯 Prove in Workshop: choice_default_access, control_endpoint_acl | H24: 🎯 Prove in Workshop: choice_default_access, control_endpoint_acl | I24: ✅ Validate in POC | J24: =IF(E24="","",5-E24) -> 0
A25: Choice | B25: choice_obo | C25: =Assessment!B11 -> Agents access external systems with the requesting user's own permissions (on-behalf-of), not shared or service principal accounts. | D25: capability | E25: =Assessment!C11 -> 1 | F25: =IF(E25="","",IF(E25<=2,G25,IF(E25<=4,H25,I25))) -> 🎯 Prove in Workshop: control_mcp_policy | G25: 🎯 Prove in Workshop: control_mcp_policy | H25: 🎯 Prove in Workshop: control_mcp_policy | I25: ✅ Validate in POC | J25: =IF(E25="","",5-E25) -> 4
A26: Choice | B26: choice_model_governance | C26: =Assessment!B12 -> Model selection is governed by a defined approval process with an owner and we can ban a model provider or family org-wide in a single action (by provider, country of origin, or approval status). | D26: capability | E26: =Assessment!C12 -> 2 | F26: =IF(E26="","",IF(E26<=2,G26,IF(E26<=4,H26,I26))) -> 🎯 Prove in Workshop: choice_smart_routing | G26: 🎯 Prove in Workshop: choice_smart_routing | H26: 🎯 Prove in Workshop: choice_smart_routing | I26: ✅ Validate in POC | J26: =IF(E26="","",5-E26) -> 3
A27: Choice | B27: choice_coding_agents | C27: =Assessment!B13 -> Coding-agent model choice and tool access (approved model list, read-vs-write tool restrictions) are defined and enforced centrally. | D27: capability | E27: =Assessment!C13 -> 3 | F27: =IF(E27="","",IF(E27<=2,G27,IF(E27<=4,H27,I27))) -> 🔍 Explore in Accelerator: Coding Agents, Skills | G27: 🔍 Explore in Accelerator: Coding Agents, Skills | H27: 🔍 Explore in Accelerator: Coding Agents, Skills | I27: ✅ Validate in POC | J27: =IF(E27="","",5-E27) -> 2
A28: Choice | B28: choice_external_routed | C28: =Assessment!B14 -> Our AI assets (vendor- or self hosted) are routed through the governed control plane, not connected directly and unmanaged. | D28: foundational | E28: =Assessment!C14 -> 4 | F28: =IF(E28="","",IF(E28<=2,G28,IF(E28<=4,H28,I28))) -> 🔍 Explore in Accelerator: External Providers | G28: ⛔ Blocking Prerequisite: Identify existing external providers, obtain a test API key, and allowlist egress [only if external_providers in scope] | H28: 🔍 Explore in Accelerator: External Providers | I28: ✅ Validate in POC | J28: =IF(E28="","",5-E28) -> 1
A29: Choice | B29: choice_open_weight_models | C29: =Assessment!B15 -> We have the option to use the latest proprietary and open weight frontier models from leading AI labs | D29: capability | E29: =Assessment!C15 -> 4 | F29: =IF(E29="","",IF(E29<=2,G29,IF(E29<=4,H29,I29))) -> 🎯 Prove in Workshop: use_open_weight_model | G29: 🎯 Prove in Workshop: use_open_weight_model | H29: 🎯 Prove in Workshop: use_open_weight_model | I29: ✅ Validate in POC | J29: =IF(E29="","",5-E29) -> 1
A30: Cost | B30: cost_unified_visibility | C30: =Assessment!B18 -> We have unified visibility into our AI spend across models, providers, teams, and use cases. | D30: foundational | E30: =Assessment!C18 -> 1 | F30: =IF(E30="","",IF(E30<=2,G30,IF(E30<=4,H30,I30))) -> ⛔ Blocking Prerequisite: Grant system.ai_gateway to the app service principal | G30: ⛔ Blocking Prerequisite: Grant system.ai_gateway to the app service principal | H30: 🎯 Prove in Workshop: cost_model_panel, cost_spend_by_model | I30: ✅ Validate in POC | J30: =IF(E30="","",5-E30) -> 4
A31: Cost | B31: cost_routing | C31: =Assessment!B19 -> We route each request to an appropriately-priced model and can quantify the savings versus always using the most expensive model. | D31: capability | E31: =Assessment!C19 -> 2 | F31: =IF(E31="","",IF(E31<=2,G31,IF(E31<=4,H31,I31))) -> 🎯 Prove in Workshop: choice_smart_routing, cost_model_panel, cost_routing_compare | G31: 🎯 Prove in Workshop: choice_smart_routing, cost_model_panel, cost_routing_compare | H31: 🎯 Prove in Workshop: choice_smart_routing, cost_model_panel, cost_routing_compare | I31: ✅ Validate in POC | J31: =IF(E31="","",5-E31) -> 3
A32: Cost | B32: cost_attribution | C32: =Assessment!B20 -> We can attribute AI cost granularly by user, team, model, tool, use case, or tag. | D32: capability | E32: =Assessment!C20 -> 3 | F32: =IF(E32="","",IF(E32<=2,G32,IF(E32<=4,H32,I32))) -> 🎯 Prove in Workshop: cost_spend_by_model, cost_usage | G32: 🎯 Prove in Workshop: cost_spend_by_model, cost_usage | H32: 🎯 Prove in Workshop: cost_spend_by_model, cost_usage | I32: ✅ Validate in POC | J32: =IF(E32="","",5-E32) -> 2
A33: Cost | B33: cost_budgets | C33: =Assessment!B21 -> We set and enforce AI budgets at the user, team, workspace, or account level and assign an appropriate owner. | D33: capability | E33: =Assessment!C21 -> 4 | F33: =IF(E33="","",IF(E33<=2,G33,IF(E33<=4,H33,I33))) -> 🎯 Prove in Workshop: cost_budgets | G33: 🎯 Prove in Workshop: cost_budgets | H33: 🎯 Prove in Workshop: cost_budgets | I33: ✅ Validate in POC | J33: =IF(E33="","",5-E33) -> 1
A34: Cost | B34: cost_task_spend | C34: =Assessment!B22 -> We can link AI-completed tasks with AI spend to understand which models are most efficient for our work | D34: capability | E34: =Assessment!C22 -> 5 | F34: =IF(E34="","",IF(E34<=2,G34,IF(E34<=4,H34,I34))) -> ✅ Validate in POC | G34: 🎯 Prove in Workshop: cost_usage, cost_task_usage | H34: 🎯 Prove in Workshop: cost_usage, cost_task_usage | I34: ✅ Validate in POC | J34: =IF(E34="","",5-E34) -> 0
A35: Cost | B35: cost_rate_limits | C35: =Assessment!B23 -> We enforce rate limits (QPM / TPM) on model and MCP services to manage capacity and cost. | D35: capability | E35: =Assessment!C23 -> 1 | F35: =IF(E35="","",IF(E35<=2,G35,IF(E35<=4,H35,I35))) -> 🎯 Prove in Workshop: cost_rate_limits | G35: 🎯 Prove in Workshop: cost_rate_limits | H35: 🎯 Prove in Workshop: cost_rate_limits | I35: ✅ Validate in POC | J35: =IF(E35="","",5-E35) -> 4
A36: Cost | B36: cost_hard_caps | C36: =Assessment!B24 -> We have hard spend caps that automatically halt or throttle requests when a budget is exceeded — not just soft alerts. | D36: capability | E36: =Assessment!C24 -> 1 | F36: =IF(E36="","",IF(E36<=2,G36,IF(E36<=4,H36,I36))) -> 🎯 Prove in Workshop: cost_rate_limits, cost_budgets | G36: 🎯 Prove in Workshop: cost_rate_limits, cost_budgets | H36: 🎯 Prove in Workshop: cost_rate_limits, cost_budgets | I36: ✅ Validate in POC | J36: =IF(E36="","",5-E36) -> 4
A37: Cost | B37: cost_anomaly | C37: =Assessment!B25 -> We detect runaway or anomalous AI spend early (retry loops, weekend experiments, sudden 100x spikes). | D37: capability | E37: =Assessment!C25 -> 1 | F37: =IF(E37="","",IF(E37<=2,G37,IF(E37<=4,H37,I37))) -> 🎯 Prove in Workshop: cost_budgets | G37: 🎯 Prove in Workshop: cost_budgets | H37: 🎯 Prove in Workshop: cost_budgets | I37: ✅ Validate in POC | J37: =IF(E37="","",5-E37) -> 4
A38: Cost | B38: cost_coding_agents | C38: =Assessment!B26 -> Coding-agent spend is attributable by team, repo, or cost center — not a single vendor invoice line — and we know whether seat-based or token-based is the bigger driver. | D38: capability | E38: =Assessment!C26 -> 1 | F38: =IF(E38="","",IF(E38<=2,G38,IF(E38<=4,H38,I38))) -> 🔍 Explore in Accelerator: Coding Agents | G38: 🔍 Explore in Accelerator: Coding Agents | H38: 🔍 Explore in Accelerator: Coding Agents | I38: ✅ Validate in POC | J38: =IF(E38="","",5-E38) -> 4
A39: Cost | B39: cost_business_case | C39: =Assessment!B27 -> AI spend spikes tie to an approved business case / owner (purchase-order or chargeback discipline). | D39: capability | E39: =Assessment!C27 -> 1 | F39: =IF(E39="","",IF(E39<=2,G39,IF(E39<=4,H39,I39))) -> 🎯 Prove in Workshop: cost_team_governance | G39: 🎯 Prove in Workshop: cost_team_governance | H39: 🎯 Prove in Workshop: cost_team_governance | I39: ✅ Validate in POC | J39: =IF(E39="","",5-E39) -> 4
A40: Control | B40: control_guardrails | C40: =Assessment!B30 -> We apply content guardrails / service policies to AI requests AND responses, authored centrally as one layer across the models and services we register. | D40: capability | E40: =Assessment!C30 -> 1 | F40: =IF(E40="","",IF(E40<=2,G40,IF(E40<=4,H40,I40))) -> 🎯 Prove in Workshop: control_guardrails | G40: 🎯 Prove in Workshop: control_guardrails | H40: 🎯 Prove in Workshop: control_guardrails | I40: ✅ Validate in POC | J40: =IF(E40="","",5-E40) -> 4
A41: Control | B41: control_pii | C41: =Assessment!B31 -> We detect and handle PII/PHI/PCI in AI requests and responses to meet compliance requirements, and we distinguish masking from blocking. | D41: foundational | E41: =Assessment!C31 -> 1 | F41: =IF(E41="","",IF(E41<=2,G41,IF(E41<=4,H41,I41))) -> ⛔ Blocking Prerequisite: External-storage catalog for inference tables, with private networking tested [only if guardrails in scope] | G41: ⛔ Blocking Prerequisite: External-storage catalog for inference tables, with private networking tested [only if guardrails in scope] | H41: 🎯 Prove in Workshop: control_guardrails | I41: ✅ Validate in POC | J41: =IF(E41="","",5-E41) -> 4
A42: Control | B42: control_prompt_injection | C42: =Assessment!B32 -> We have protections against prompt injection / jailbreak and policy violations, including for customer-facing AI. | D42: capability | E42: =Assessment!C32 -> 1 | F42: =IF(E42="","",IF(E42<=2,G42,IF(E42<=4,H42,I42))) -> 🎯 Prove in Workshop: control_guardrails | G42: 🎯 Prove in Workshop: control_guardrails | H42: 🎯 Prove in Workshop: control_guardrails | I42: ✅ Validate in POC | J42: =IF(E42="","",5-E42) -> 4
...
